<?xml version="1.0"?>
<robot name="robot_mov">

    <material name="Black">
        <color rgba="0.0 0.0 0.0 1.0"/>
    </material>
    <material name="White">
        <color rgba="1.0 1.0 1.0 1.0"/>
    </material>

    <gazebo>
        <plugin name="gazebo_ros_control" filename="libgazebo_ros_control.so">
            <robotNamespace>/robot_mov</robotNamespace>
            <robotSimType>gazebo_ros_control/DefaultRobotHWSim</robotSimType>
        </plugin>
    </gazebo>

    <link name="chassis">
        <inertial>
            <mass value="5.0"/>
            <inertia ixx="3.02083333333" ixy="0.0" ixz="0.0" iyy="3.02083333333" iyz="0.0" izz="5.20833333333"/>
        </inertial>
        <visual>
            <origin xyz="0.0 0.0 0.0" rpy="0.0 0.0 0.0"/>
            <geometry>
                <box size="2.5 2.5 1.0"/>
            </geometry>
        </visual>
        <collision>
            <origin xyz="0.0 0.0 0.0" rpy="0.0 0.0 0.0"/>
            <geometry>
                <box size="2.5 2.5 1.0"/>
            </geometry>
        </collision>
    </link>

    <link name="right_front_wheel">
        <inertial>
                <origin xyz="0.0 0.0 0.0" rpy="0.0 0.0 0.0"/>
                <mass value="0.2"/>
                <inertia ixx="0.0131666666667" ixy="0.0" ixz="0.0" iyy="0.0131666666667" iyz="0.0" izz="0.025"/>
        </inertial>
        <visual>
            <origin xyz="0.0 0.0 0.0" rpy="0.0 0.0 0.0"/>
            <geometry>
                <cylinder radius="0.5" length="0.2"/>
            </geometry>
        </visual>
        <collision>
            <origin rpy="0 0 0" xyz="0 0 0"/>
            <geometry>
                <cylinder radius="0.5" length="0.2"/>
            </geometry>
        </collision>
    </link>

    <joint name="right_front_wheel_joint" type="continuous">
        <origin xyz="-1.35 -0.75 -0.5" rpy="0.0 1.5708 0.0"/>
        <parent link="chassis"/>
        <child link="right_front_wheel"/>
        <axis xyz="0.0 0.0 1.0"/>
        <limit effort="100" velocity="100"/>
        <dynamics damping="0.0" friction="0.0"/>   
    </joint>

    <link name="left_front_wheel">
        <inertial>
                <origin xyz="0.0 0.0 0.0" rpy="0.0 0.0 0.0"/>
                <mass value="0.2"/>
                <inertia ixx="0.0131666666667" ixy="0.0" ixz="0.0" iyy="0.0131666666667" iyz="0.0" izz="0.025"/>
        </inertial>
        <visual>
            <origin xyz="0.0 0.0 0.0" rpy="0.0 0.0 0.0"/>
            <geometry>
                <cylinder radius="0.5" length="0.2"/>
            </geometry>
        </visual>
        <collision>
            <origin rpy="0 0 0" xyz="0 0 0"/>
            <geometry>
                <cylinder radius="0.5" length="0.2"/>
            </geometry>
        </collision>
    </link>

    <joint name="left_front_wheel_joint" type="continuous">
        <origin xyz="1.35 -0.75 -0.5" rpy="0.0 1.5708 0.0"/>
        <parent link="chassis"/>
        <child link="left_front_wheel"/>
        <axis xyz="0.0 0.0 1.0"/>
        <limit effort="100" velocity="100"/>
        <dynamics damping="0.0" friction="0.0"/>    
    </joint>

    <link name="right_back_wheel">
        <inertial>
                <origin xyz="0.0 0.0 0.0" rpy="0.0 0.0 0.0"/>
                <mass value="0.2"/>
                <inertia ixx="0.0131666666667" ixy="0.0" ixz="0.0" iyy="0.0131666666667" iyz="0.0" izz="0.025"/>
        </inertial>
        <visual>
            <origin xyz="0.0 0.0 0.0" rpy="0.0 0.0 0.0"/>
            <geometry>
                <cylinder radius="0.5" length="0.2"/>
            </geometry>
        </visual>
        <collision>
            <origin rpy="0 0 0" xyz="0 0 0"/>
            <geometry>
                <cylinder radius="0.5" length="0.2"/>
            </geometry>
        </collision>
    </link>

    <joint name="right_back_wheel_joint" type="continuous">
        <origin xyz="-1.35 0.75 -0.5" rpy="0.0 1.5708 0.0"/>
        <parent link="chassis"/>
        <child link="right_back_wheel"/>
        <axis xyz="0.0 0.0 1.0"/>
        <limit effort="100" velocity="100"/>
        <dynamics damping="0.0" friction="0.0"/>
    </joint>

    <link name="left_back_wheel">
        <inertial>
                <origin xyz="0.0 0.0 0.0" rpy="0.0 0.0 0.0"/>
                <mass value="0.2"/>
                <inertia ixx="0.0131666666667" ixy="0.0" ixz="0.0" iyy="0.0131666666667" iyz="0.0" izz="0.025"/>
        </inertial>
        <visual>
            <origin xyz="0.0 0.0 0.0" rpy="0.0 0.0 0.0"/>
            <geometry>
                <cylinder radius="0.5" length="0.2"/>
            </geometry>
        </visual>
        <collision>
            <origin rpy="0 0 0" xyz="0 0 0"/>
            <geometry>
                <cylinder radius="0.5" length="0.2"/>
            </geometry>
        </collision>
    </link>

    <joint name="left_back_wheel_joint" type="continuous">
        <origin xyz="1.35 0.75 -0.5" rpy="0.0 1.5708 0.0"/>
        <parent link="chassis"/>
        <child link="left_back_wheel"/>
        <axis xyz="0.0 0.0 1.0"/>
        <limit effort="100" velocity="100"/>
        <dynamics damping="0.0" friction="0.0"/>
    </joint>

    <gazebo reference="chassis">
        <turnGravityOff>false</turnGravityOff>
    </gazebo>

    <gazebo reference="right_front_wheel">
        <mu1 value="200.0"/>
        <mu2 value="100.0"/>
        <kp value="10000000.0"/>
        <kd value="1.0"/>
        <material>Gazebo/Black</material>
    </gazebo>

    <gazebo reference="right_back_wheel">
        <mu1 value="200.0"/>
        <mu2 value="100.0"/>
        <kp value="10000000.0"/>
        <kd value="1.0"/>
        <material>Gazebo/Black</material>
    </gazebo>

    <gazebo reference="left_front_wheel">
        <mu1 value="200.0"/>
        <mu2 value="100.0"/>
        <kp value="10000000.0"/>
        <kd value="1.0"/>
        <material>Gazebo/Black</material>
    </gazebo>

    <gazebo reference="left_back_wheel">
        <mu1 value="200.0"/>
        <mu2 value="100.0"/>
        <kp value="10000000.0"/>
        <kd value="1.0"/>
        <material>Gazebo/Black</material>
    </gazebo>


    <transmission name="left_back_wheel_trans">
        <type>transmission_interface/SimpleTransmission</type>
        <actuator name="left_back_wheel_motor">
        <hardwareInterface>EffortJointInterface</hardwareInterface>
        <mechanicalReduction>1</mechanicalReduction>
        </actuator>
        <joint name="left_back_wheel_joint">
            <hardwareInterface>VelocityJointInterface</hardwareInterface>
        </joint>
    </transmission>

    <transmission name="right_front_wheel_trans">
        <type>transmission_interface/SimpleTransmission</type>
        <actuator name="right_front_wheel_motor">
            <hardwareInterface>EffortJointInterface</hardwareInterface>
            <mechanicalReduction>1</mechanicalReduction>
        </actuator>
        <joint name="right_front_wheel_joint">
        <hardwareInterface>VelocityJointInterface</hardwareInterface>
        </joint>
    </transmission>

    <transmission name="right_back_wheel_trans">
        <type>transmission_interface/SimpleTransmission</type>
        <actuator name="right_back_wheel_motor">
        <hardwareInterface>EffortJointInterface</hardwareInterface>
        <mechanicalReduction>1</mechanicalReduction>
        </actuator>
        <joint name="right_back_wheel_joint">
            <hardwareInterface>VelocityJointInterface</hardwareInterface>
        </joint>
    </transmission>

    <transmission name="left_front_wheel_trans">
        <type>transmission_interface/SimpleTransmission</type>
        <actuator name="left_front_wheel_motor">
            <hardwareInterface>EffortJointInterface</hardwareInterface>
            <mechanicalReduction>1</mechanicalReduction>
        </actuator>
        <joint name="left_front_wheel_joint">
        <hardwareInterface>VelocityJointInterface</hardwareInterface>
        </joint>
    </transmission>

   





    
</robot>